<?xml version="1.0" encoding="utf-8"?>

<robot name="carver_description" xmlns:xacro="http://www.ros.org/wiki/xacro">

  <xacro:include filename="inertial_macros.xacro" />

  <link name="base_footprint"></link>

  <joint name="base_joint" type="fixed">
    <parent link="base_footprint"/>
    <child link="base_link"/>
    <origin xyz="0.0 0.0 0.345" rpy="0 0 0"/>
  </joint>

  <link
    name="base_link">
    <xacro:inertial_box mass="3.0" x="0.63598" y="0.79085" z="0.10">
        <origin xyz="0.0765717108056987 -0.000305321354473288 0.182746551264274" rpy="0 0 0"/>
    </xacro:inertial_box>

    <visual>
      <origin
        xyz="0 0 0"
        rpy="0 0 0" />
      <geometry>
        <mesh
          filename="file:///$(find carver_description)/meshes/base_link.STL" />
      </geometry>
      <material
        name="">
        <color
          rgba="0.792156862745098 0.819607843137255 0.933333333333333 1" />
      </material>
    </visual>
    <collision>
      <origin
        xyz="0 0 0"
        rpy="0 0 0" />
      <geometry>
        <mesh
          filename="file:///$(find carver_description)/meshes/base_link.STL" />
      </geometry>
    </collision>
  </link>


  <link
    name="front_right_sterring_Link">
    <inertial>
      <origin
        xyz="-6.87012402522669E-09 3.51066137271872E-09 -0.0112499999237069"
        rpy="0 0 0" />
      <mass value="0.1" />
      <inertia 
        ixx="0.00525" 
        ixy="0.0" 
        ixz="0.0"
        iyy="0.00035" 
        iyz="0.0" 
        izz="0.00525" />
    </inertial>
    <visual>
      <origin
        xyz="0 0 0"
        rpy="0 0 0" />
      <geometry>
        <mesh
          filename="file:///$(find carver_description)/meshes/front_right_sterring_Link.STL" />
      </geometry>
      <material
        name="">
        <color
          rgba="0.792156862745098 0.819607843137255 0.933333333333333 1" />
      </material>
    </visual>
    <collision>
      <origin
        xyz="0 0 0"
        rpy="0 0 0" />
      <geometry>
        <mesh
          filename="file:///$(find carver_description)/meshes/front_right_sterring_Link.STL" />
      </geometry>
    </collision>
  </link>
  <joint
    name="base_front_right_sterring_joint"
    type="revolute">
    <origin
      xyz="0.639118924633511 -0.284499999999994 -0.158749999999999"
      rpy="0 0 0" />
    <parent
      link="base_link" />
    <child
      link="front_right_sterring_Link" />
    <axis
      xyz="0 0 -1" />
    <limit lower="-1.49" upper="1.49" effort="1000" velocity="1.0" />
    <dynamics damping="1.0" friction="2.0"/>
  </joint>
  <link
    name="front_right_wheel_Link">
    <!-- <inertial>
      <origin
        xyz="0.00138386531093282 8.32667268468867E-17 0.0379747931765428"
        rpy="0 0 0" />
      <mass value="0.5" />
      <inertia ixx="0.01055" ixy="0" ixz="0" iyy="0.00075" iyz="0" izz="0.01055" /> 
    </inertial> -->
    <xacro:inertial_cylinder mass="0.1" length="0.65" radius="0.175">
      <origin
        xyz="0.00138386531093282 8.32667268468867E-17 0.0379747931765428"
        rpy="0 0 0" />
    </xacro:inertial_cylinder>
    <visual>
      <origin
        xyz="0 0 0"
        rpy="0 0 0" />
      <geometry>
        <mesh
          filename="file:///$(find carver_description)/meshes/front_right_wheel_Link.STL" />
      </geometry>
      <material
        name="">
        <color
          rgba="0.792156862745098 0.819607843137255 0.933333333333333 1" />
      </material>
    </visual>
    <collision>
      <origin
        xyz="0 0 0"
        rpy="0 0 0" />
      <geometry>
        <mesh
          filename="file:///$(find carver_description)/meshes/front_right_wheel_Link.STL" />
      </geometry>
    </collision>
  </link>
  <joint
    name="front_right_steering_front_right_wheel_joint"
    type="continuous">
    <origin
      xyz="-0.00404234340824972 -0.110926369542007 -0.0112500000000002"
      rpy="-1.5707963267949 0 0" />
    <parent
      link="front_right_sterring_Link" />
    <child
      link="front_right_wheel_Link" />
    <axis
      xyz="0.036417508182449 0 0.999336662540598" />
    <limit
      effort="100"
      velocity="100" />
  </joint>
  <link
    name="front_left_sterring_Link">
    <inertial>
      <origin
        xyz="7.10743075504894E-09 -3.0012958229797E-09 -0.0112499999237069"
        rpy="0 0 0" />
      <mass value="0.1" />
      <inertia 
        ixx="0.00525" 
        ixy="0.0" 
        ixz="0.0"
        iyy="0.00035" 
        iyz="0.0" 
        izz="0.00525" />
    </inertial>
    <visual>
      <origin
        xyz="0 0 0"
        rpy="0 0 0" />
      <geometry>
        <mesh
          filename="file:///$(find carver_description)/meshes/front_left_sterring_Link.STL" />
      </geometry>
      <material
        name="">
        <color
          rgba="0.792156862745098 0.819607843137255 0.933333333333333 1" />
      </material>
    </visual>
    <collision>
      <origin
        xyz="0 0 0"
        rpy="0 0 0" />
      <geometry>
        <mesh
          filename="file:///$(find carver_description)/meshes/front_left_sterring_Link.STL" />
      </geometry>
    </collision>
  </link>
  <joint
    name="base_front_left_sterring_joint"
    type="revolute">
    <origin
      xyz="0.639118924633511 0.284499999999994 -0.158749999999999"
      rpy="0 0 0" />
    <parent
      link="base_link" />
    <child
      link="front_left_sterring_Link" />
    <axis
      xyz="0 0 -1" />
    <limit lower="-1.49" upper="1.49" effort="1000" velocity="1.0" />
    <dynamics damping="1.0" friction="2.0"/>
  </joint>
  <link
    name="front_left_wheel_Link">
    <!-- <inertial>
      <origin
        xyz="0.00138386531093293 1.38777878078145E-16 -0.0379747931765427"
        rpy="0 0 0" />
      <mass value="0.5" />
      <inertia ixx="0.01055" ixy="0" ixz="0" iyy="0.00075" iyz="0" izz="0.01055" /> 
    </inertial> -->
    <xacro:inertial_cylinder mass="0.1" length="0.65" radius="0.175">
      <origin
        xyz="0.00138386531093293 1.38777878078145E-16 -0.0379747931765427"
        rpy="0 0 0" />
    </xacro:inertial_cylinder>
    <visual>
      <origin
        xyz="0 0 0"
        rpy="0 0 0" />
      <geometry>
        <mesh
          filename="file:///$(find carver_description)/meshes/front_left_wheel_Link.STL" />
      </geometry>
      <material
        name="">
        <color
          rgba="0.792156862745098 0.819607843137255 0.933333333333333 1" />
      </material>
    </visual>
    <collision>
      <origin
        xyz="0 0 0"
        rpy="0 0 0" />
      <geometry>
        <mesh
          filename="file:///$(find carver_description)/meshes/front_left_wheel_Link.STL" />
      </geometry>
    </collision>
  </link>
  <joint
    name="front_left_steering_front_left_wheel_joint"
    type="continuous">
    <origin
      xyz="-0.00404234340824972 0.110926369542007 -0.0112500000000002"
      rpy="-1.5707963267949 0 0" />
    <parent
      link="front_left_sterring_Link" />
    <child
      link="front_left_wheel_Link" />
    <axis
      xyz="0.036417508182449 0 -0.999336662540598" />
    <limit
      effort="100"
      velocity="100" />
  </joint>
  <link
    name="rear_right_wheel_Link">
    <!-- <inertial>
      <origin
        xyz="-1.11022302462516E-16 -8.32667268468867E-17 0.0379999999999999"
        rpy="0 0 0" />
      <mass value="0.5" />
      <inertia ixx="0.01055" ixy="0" ixz="0" iyy="0.00075" iyz="0" izz="0.01055" /> 
    </inertial> -->
    <xacro:inertial_cylinder mass="0.1" length="0.65" radius="0.175">
      <origin
        xyz="-1.11022302462516E-16 -8.32667268468867E-17 0.0379999999999999"
        rpy="0 0 0" />
    </xacro:inertial_cylinder>
    <visual>
      <origin
        xyz="0 0 0"
        rpy="0 0 0" />
      <geometry>
        <mesh
          filename="file:///$(find carver_description)/meshes/rear_right_wheel_Link.STL" />
      </geometry>
      <material
        name="">
        <color
          rgba="0.792156862745098 0.819607843137255 0.933333333333333 1" />
      </material>
    </visual>
    <collision>
      <origin
        xyz="0 0 0"
        rpy="0 0 0" />
      <geometry>
        <mesh
          filename="file:///$(find carver_description)/meshes/rear_right_wheel_Link.STL" />
      </geometry>
    </collision>
  </link>
  <joint
    name="base_rear_right_wheel_joint"
    type="continuous">
    <origin
      xyz="-0.636881075366491 -0.3955 -0.17"
      rpy="-1.5707963267949 0 0" />
    <parent
      link="base_link" />
    <child
      link="rear_right_wheel_Link" />
    <axis
      xyz="0 0 1" />
    <limit
      effort="100"
      velocity="100" />
  </joint>
  <link
    name="rear_left_wheel_Link">
    <!-- <inertial>
      <origin
        xyz="-1.11022302462516E-16 -5.55111512312578E-17 -0.038"
        rpy="0 0 0" />
      <mass value="0.5" />
      <inertia ixx="0.01055" ixy="0" ixz="0" iyy="0.00075" iyz="0" izz="0.01055" /> 
    </inertial> -->
    <xacro:inertial_cylinder mass="0.1" length="0.65" radius="0.175">
      <origin
        xyz="-1.11022302462516E-16 -5.55111512312578E-17 0.0379999999999999"
        rpy="0 0 0" />
    </xacro:inertial_cylinder>
    <visual>
      <origin
        xyz="0 0 0"
        rpy="0 0 0" />
      <geometry>
        <mesh
          filename="file:///$(find carver_description)/meshes/rear_left_wheel_Link.STL" />
      </geometry>
      <material
        name="">
        <color
          rgba="0.792156862745098 0.819607843137255 0.933333333333333 1" />
      </material>
    </visual>
    <collision>
      <origin
        xyz="0 0 0"
        rpy="0 0 0" />
      <geometry>
        <mesh
          filename="file:///$(find carver_description)/meshes/rear_left_wheel_Link.STL" />
      </geometry>
    </collision>
  </link>
  <joint
    name="base_rear_left_wheel_joint"
    type="continuous">
    <origin
      xyz="-0.636881075366491 0.3955 -0.17"
      rpy="-1.5707963267949 0 0" />
    <parent
      link="base_link" />
    <child
      link="rear_left_wheel_Link" />
    <axis
      xyz="0 0 1" />
    <limit
      effort="100"
      velocity="100" />
  </joint>
<!-- /////////////////////////////// -->

  <link
    name="C16_Link">
    <inertial>
      <origin
        xyz="-0.00088474978448877 0.0 0.00143612694647577"
        rpy="0 0 0" />
      <mass
        value="0.01" />
      <inertia
        ixx="0.000791421263365419"
        ixy="0.0"
        ixz="0.0"
        iyy="0.000800507843146539"
        iyz="0.00"
        izz="0.000866550903215115" />
    </inertial>
    <visual>
      <origin
        xyz="0 0 0"
        rpy="0 0 0" />
      <geometry>
        <mesh
          filename="file:///$(find carver_description)/meshes/C16_Link.STL" />
      </geometry>
      <material
        name="">
        <color
          rgba="0.792156862745098 0.819607843137255 0.933333333333333 1" />
      </material>
    </visual>
    <collision>
      <origin
        xyz="0 0 0"
        rpy="0 0 0" />
      <geometry>
        <mesh
          filename="file:///$(find carver_description)/meshes/C16_Link.STL" />
      </geometry>
    </collision>
  </link>
  <joint
    name="base_C16_joint"
    type="fixed">
    <origin
      xyz="0.237767026438191 0 1.56788196587259"
      rpy="0 0 0" />
    <parent
      link="base_link" />
    <child
      link="C16_Link" />
    <axis
      xyz="0 0 0" />
  </joint>
  <link
    name="T265_Link">
    <inertial>
      <origin
        xyz="-0.00700393876079974 -0.00123869269728641 -9.55081819808967E-06"
        rpy="0 0 0" />
      <mass
        value="0.01" />
      <inertia
        ixx="1.39361946583924E-05"
        ixy="1.34672770579493E-08"
        ixz="1.90513550223783E-09"
        iyy="9.41413823478598E-07"
        iyz="4.36675000350756E-09"
        izz="1.32399745397941E-05" />
    </inertial>
    <visual>
      <origin
        xyz="0 0 0"
        rpy="0 0 0" />
      <geometry>
        <mesh
          filename="file:///$(find carver_description)/meshes/T265_Link.STL" />
      </geometry>
      <material
        name="">
        <color
          rgba="0.752941176470588 0.752941176470588 0.752941176470588 1" />
      </material>
    </visual>
    <collision>
      <origin
        xyz="0 0 0"
        rpy="0 0 0" />
      <geometry>
        <mesh
          filename="file:///$(find carver_description)/meshes/T265_Link.STL" />
      </geometry>
    </collision>
  </link>
  <joint
    name="base_T265_joint"
    type="fixed">
    <origin
      xyz="0.914568924633506 0.000699999999822833 0.423999999999455"
      rpy="0 0 0" />
    <parent
      link="base_link" />
    <child
      link="T265_Link" />
    <axis
      xyz="0 0 0" />
  </joint>
  <link
    name="L515_Link">
    <inertial>
      <origin
        xyz="-0.0138329335160927 0.000212766276144195 -0.0151333320328252"
        rpy="0 0 0" />
      <mass
        value="0.01" />
      <inertia
        ixx="2.29233885806633E-05"
        ixy="-3.43966785553731E-08"
        ixz="-9.60811102903896E-09"
        iyy="1.23501086319306E-05"
        iyz="1.73643710033919E-07"
        izz="1.35094237257254E-05" />
    </inertial>
    <visual>
      <origin
        xyz="0 0 0"
        rpy="0 0 0" />
      <geometry>
        <mesh
          filename="file:///$(find carver_description)/meshes/L515_Link.STL" />
      </geometry>
      <material
        name="">
        <color
          rgba="0.752941176470588 0.752941176470588 0.752941176470588 1" />
      </material>
    </visual>
    <collision>
      <origin
        xyz="0 0 0"
        rpy="0 0 0" />
      <geometry>
        <mesh
          filename="file:///$(find carver_description)/meshes/L515_Link.STL" />
      </geometry>
    </collision>
  </link>
  <joint
    name="base_L515_joint"
    type="fixed">
    <origin
      xyz="0.929717002207267 -1.17161560733146E-05 -0.0149951470092575"
      rpy="0 0 0" />
    <parent
      link="base_link" />
    <child
      link="L515_Link" />
    <axis
      xyz="0 0 0" />
  </joint>

  <link
    name="LD_SICK_Link">
    <inertial>
      <origin
        xyz="-0.0476495449150161 3.70691349494235E-07 -4.44702155644183E-06"
        rpy="0 0 0" />
      <mass
        value="0.01" />
      <inertia
        ixx="0.00155787250018401"
        ixy="-1.82431705564109E-09"
        ixz="2.07922879380138E-08"
        iyy="0.0012763862501827"
        iyz="-1.43394136883926E-08"
        izz="0.00165040465761084" />
    </inertial>
    <visual>
      <origin
        xyz="0 0 0"
        rpy="0 0 0" />
      <geometry>
        <mesh
          filename="file:///$(find carver_description)/meshes/LD_SICK_Link.STL" />
      </geometry>
      <material
        name="">
        <color
          rgba="0.792156862745098 0.819607843137255 0.933333333333333 1" />
      </material>
    </visual>
    <collision>
      <origin
        xyz="0 0 0"
        rpy="0 0 0" />
      <geometry>
        <mesh
          filename="file:///$(find carver_description)/meshes/LD_SICK_Link.STL" />
      </geometry>
    </collision>
  </link>
  <joint
    name="base_LD_SICK_joint"
    type="fixed">
    <origin
      xyz="0.942318924633513 0 0.215"
      rpy="0 0 0" />
    <parent
      link="base_link" />
    <child
      link="LD_SICK_Link" />
    <axis
      xyz="0 0 0" />
  </joint>

</robot>